2019-09-17 13:24:25,693 [ERROR]  Invalid response object for url b'/webhooks/telegram/webhook', Expected Type: HTTPResponse, Actual Type: <class 'NoneType'>
2019-09-17 13:24:25,724 [ERROR]  Exception occurred while handling uri: 'http://8d2b559b.ngrok.io/webhooks/telegram/webhook'
Traceback (most recent call last):
  File "/home/on/Documents/kp-dds/venvest/lib/python3.6/site-packages/sanic/server.py", line 417, in write_response
    response.output(
AttributeError: 'NoneType' object has no attribute 'output'
2019-09-17 13:24:26,702 [ERROR]  Exception occurred while handling uri: 'http://8d2b559b.ngrok.io/favicon.ico'
Traceback (most recent call last):
  File "/home/on/Documents/kp-dds/venvest/lib/python3.6/site-packages/sanic/app.py", line 893, in handle_request
    handler, args, kwargs, uri = self.router.get(request)
  File "/home/on/Documents/kp-dds/venvest/lib/python3.6/site-packages/sanic/router.py", line 407, in get
    return self._get(request.path, request.method, "")
  File "/home/on/Documents/kp-dds/venvest/lib/python3.6/site-packages/sanic/router.py", line 469, in _get
    raise NotFound("Requested URL {} not found".format(url))
sanic.exceptions.NotFound: Requested URL /favicon.ico not found
2019-09-17 13:24:39,968 [ERROR]  Invalid response object for url b'/webhooks/telegram/webhook', Expected Type: HTTPResponse, Actual Type: <class 'NoneType'>
2019-09-17 13:24:39,969 [ERROR]  Exception occurred while handling uri: 'http://localhost:5005/webhooks/telegram/webhook'
Traceback (most recent call last):
  File "/home/on/Documents/kp-dds/venvest/lib/python3.6/site-packages/sanic/server.py", line 417, in write_response
    response.output(
AttributeError: 'NoneType' object has no attribute 'output'
2019-09-17 13:24:40,120 [ERROR]  Exception occurred while handling uri: 'http://localhost:5005/favicon.ico'
Traceback (most recent call last):
  File "/home/on/Documents/kp-dds/venvest/lib/python3.6/site-packages/sanic/app.py", line 893, in handle_request
    handler, args, kwargs, uri = self.router.get(request)
  File "/home/on/Documents/kp-dds/venvest/lib/python3.6/site-packages/sanic/router.py", line 407, in get
    return self._get(request.path, request.method, "")
  File "/home/on/Documents/kp-dds/venvest/lib/python3.6/site-packages/sanic/router.py", line 469, in _get
    raise NotFound("Requested URL {} not found".format(url))
sanic.exceptions.NotFound: Requested URL /favicon.ico not found
2019-09-17 13:24:46,454 [ERROR]  Exception occurred while handling uri: 'http://localhost:5005/webhooks/'
Traceback (most recent call last):
  File "/home/on/Documents/kp-dds/venvest/lib/python3.6/site-packages/sanic/app.py", line 893, in handle_request
    handler, args, kwargs, uri = self.router.get(request)
  File "/home/on/Documents/kp-dds/venvest/lib/python3.6/site-packages/sanic/router.py", line 407, in get
    return self._get(request.path, request.method, "")
  File "/home/on/Documents/kp-dds/venvest/lib/python3.6/site-packages/sanic/router.py", line 469, in _get
    raise NotFound("Requested URL {} not found".format(url))
sanic.exceptions.NotFound: Requested URL /webhooks/ not found
2019-09-17 13:24:51,432 [ERROR]  Exception occurred while handling uri: 'http://localhost:5005/'
Traceback (most recent call last):
  File "/home/on/Documents/kp-dds/venvest/lib/python3.6/site-packages/sanic/app.py", line 893, in handle_request
    handler, args, kwargs, uri = self.router.get(request)
  File "/home/on/Documents/kp-dds/venvest/lib/python3.6/site-packages/sanic/router.py", line 407, in get
    return self._get(request.path, request.method, "")
  File "/home/on/Documents/kp-dds/venvest/lib/python3.6/site-packages/sanic/router.py", line 469, in _get
    raise NotFound("Requested URL {} not found".format(url))
sanic.exceptions.NotFound: Requested URL / not found
2019-09-17 13:24:53,735 [ERROR]  Exception occurred while handling uri: 'http://localhost:5005/'
Traceback (most recent call last):
  File "/home/on/Documents/kp-dds/venvest/lib/python3.6/site-packages/sanic/app.py", line 893, in handle_request
    handler, args, kwargs, uri = self.router.get(request)
  File "/home/on/Documents/kp-dds/venvest/lib/python3.6/site-packages/sanic/router.py", line 407, in get
    return self._get(request.path, request.method, "")
  File "/home/on/Documents/kp-dds/venvest/lib/python3.6/site-packages/sanic/router.py", line 469, in _get
    raise NotFound("Requested URL {} not found".format(url))
sanic.exceptions.NotFound: Requested URL / not found
2019-09-17 13:24:59,035 [ERROR]  Exception occurred while handling uri: 'http://localhost:5005/'
Traceback (most recent call last):
  File "/home/on/Documents/kp-dds/venvest/lib/python3.6/site-packages/sanic/app.py", line 893, in handle_request
    handler, args, kwargs, uri = self.router.get(request)
  File "/home/on/Documents/kp-dds/venvest/lib/python3.6/site-packages/sanic/router.py", line 407, in get
    return self._get(request.path, request.method, "")
  File "/home/on/Documents/kp-dds/venvest/lib/python3.6/site-packages/sanic/router.py", line 469, in _get
    raise NotFound("Requested URL {} not found".format(url))
sanic.exceptions.NotFound: Requested URL / not found
2019-09-17 13:25:15,403 [ERROR]  Exception occurred while handling uri: 'http://localhost:5005/'
Traceback (most recent call last):
  File "/home/on/Documents/kp-dds/venvest/lib/python3.6/site-packages/sanic/app.py", line 893, in handle_request
    handler, args, kwargs, uri = self.router.get(request)
  File "/home/on/Documents/kp-dds/venvest/lib/python3.6/site-packages/sanic/router.py", line 407, in get
    return self._get(request.path, request.method, "")
  File "/home/on/Documents/kp-dds/venvest/lib/python3.6/site-packages/sanic/router.py", line 469, in _get
    raise NotFound("Requested URL {} not found".format(url))
sanic.exceptions.NotFound: Requested URL / not found
